{
 "cells": [
  {
   "cell_type": "code",
   "execution_count": 5,
   "id": "b6b326ea-6ea8-4de5-a14f-10b850ecd71a",
   "metadata": {},
   "outputs": [
    {
     "name": "stdout",
     "output_type": "stream",
     "text": [
      "Epoch 1/10\n"
     ]
    },
    {
     "ename": "UnimplementedError",
     "evalue": "Graph execution error:\n\nDetected at node binary_crossentropy/Cast defined at (most recent call last):\n  File \"C:\\Users\\eddcr\\anaconda3\\lib\\runpy.py\", line 197, in _run_module_as_main\n\n  File \"C:\\Users\\eddcr\\anaconda3\\lib\\runpy.py\", line 87, in _run_code\n\n  File \"C:\\Users\\eddcr\\anaconda3\\lib\\site-packages\\ipykernel_launcher.py\", line 17, in <module>\n\n  File \"C:\\Users\\eddcr\\anaconda3\\lib\\site-packages\\traitlets\\config\\application.py\", line 846, in launch_instance\n\n  File \"C:\\Users\\eddcr\\anaconda3\\lib\\site-packages\\ipykernel\\kernelapp.py\", line 712, in start\n\n  File \"C:\\Users\\eddcr\\anaconda3\\lib\\site-packages\\tornado\\platform\\asyncio.py\", line 199, in start\n\n  File \"C:\\Users\\eddcr\\anaconda3\\lib\\asyncio\\base_events.py\", line 601, in run_forever\n\n  File \"C:\\Users\\eddcr\\anaconda3\\lib\\asyncio\\base_events.py\", line 1905, in _run_once\n\n  File \"C:\\Users\\eddcr\\anaconda3\\lib\\asyncio\\events.py\", line 80, in _run\n\n  File \"C:\\Users\\eddcr\\anaconda3\\lib\\site-packages\\ipykernel\\kernelbase.py\", line 510, in dispatch_queue\n\n  File \"C:\\Users\\eddcr\\anaconda3\\lib\\site-packages\\ipykernel\\kernelbase.py\", line 499, in process_one\n\n  File \"C:\\Users\\eddcr\\anaconda3\\lib\\site-packages\\ipykernel\\kernelbase.py\", line 406, in dispatch_shell\n\n  File \"C:\\Users\\eddcr\\anaconda3\\lib\\site-packages\\ipykernel\\kernelbase.py\", line 730, in execute_request\n\n  File \"C:\\Users\\eddcr\\anaconda3\\lib\\site-packages\\ipykernel\\ipkernel.py\", line 390, in do_execute\n\n  File \"C:\\Users\\eddcr\\anaconda3\\lib\\site-packages\\ipykernel\\zmqshell.py\", line 528, in run_cell\n\n  File \"C:\\Users\\eddcr\\anaconda3\\lib\\site-packages\\IPython\\core\\interactiveshell.py\", line 2914, in run_cell\n\n  File \"C:\\Users\\eddcr\\anaconda3\\lib\\site-packages\\IPython\\core\\interactiveshell.py\", line 2960, in _run_cell\n\n  File \"C:\\Users\\eddcr\\anaconda3\\lib\\site-packages\\IPython\\core\\async_helpers.py\", line 78, in _pseudo_sync_runner\n\n  File \"C:\\Users\\eddcr\\anaconda3\\lib\\site-packages\\IPython\\core\\interactiveshell.py\", line 3185, in run_cell_async\n\n  File \"C:\\Users\\eddcr\\anaconda3\\lib\\site-packages\\IPython\\core\\interactiveshell.py\", line 3377, in run_ast_nodes\n\n  File \"C:\\Users\\eddcr\\anaconda3\\lib\\site-packages\\IPython\\core\\interactiveshell.py\", line 3457, in run_code\n\n  File \"C:\\Users\\eddcr\\AppData\\Local\\Temp\\ipykernel_20144\\867447187.py\", line 32, in <module>\n\n  File \"C:\\Users\\eddcr\\anaconda3\\lib\\site-packages\\keras\\src\\utils\\traceback_utils.py\", line 65, in error_handler\n\n  File \"C:\\Users\\eddcr\\anaconda3\\lib\\site-packages\\keras\\src\\engine\\training.py\", line 1807, in fit\n\n  File \"C:\\Users\\eddcr\\anaconda3\\lib\\site-packages\\keras\\src\\engine\\training.py\", line 1401, in train_function\n\n  File \"C:\\Users\\eddcr\\anaconda3\\lib\\site-packages\\keras\\src\\engine\\training.py\", line 1384, in step_function\n\n  File \"C:\\Users\\eddcr\\anaconda3\\lib\\site-packages\\keras\\src\\engine\\training.py\", line 1373, in run_step\n\n  File \"C:\\Users\\eddcr\\anaconda3\\lib\\site-packages\\keras\\src\\engine\\training.py\", line 1151, in train_step\n\n  File \"C:\\Users\\eddcr\\anaconda3\\lib\\site-packages\\keras\\src\\engine\\training.py\", line 1209, in compute_loss\n\n  File \"C:\\Users\\eddcr\\anaconda3\\lib\\site-packages\\keras\\src\\engine\\compile_utils.py\", line 277, in __call__\n\n  File \"C:\\Users\\eddcr\\anaconda3\\lib\\site-packages\\keras\\src\\losses.py\", line 143, in __call__\n\n  File \"C:\\Users\\eddcr\\anaconda3\\lib\\site-packages\\keras\\src\\losses.py\", line 270, in call\n\n  File \"C:\\Users\\eddcr\\anaconda3\\lib\\site-packages\\keras\\src\\losses.py\", line 2521, in binary_crossentropy\n\nCast string to float is not supported\n\t [[{{node binary_crossentropy/Cast}}]] [Op:__inference_train_function_10902]",
     "output_type": "error",
     "traceback": [
      "\u001b[1;31m---------------------------------------------------------------------------\u001b[0m",
      "\u001b[1;31mUnimplementedError\u001b[0m                        Traceback (most recent call last)",
      "\u001b[1;32m~\\AppData\\Local\\Temp\\ipykernel_20144\\867447187.py\u001b[0m in \u001b[0;36m<module>\u001b[1;34m\u001b[0m\n\u001b[0;32m     30\u001b[0m \u001b[1;33m\u001b[0m\u001b[0m\n\u001b[0;32m     31\u001b[0m \u001b[1;31m# Train the model for 10 epochs\u001b[0m\u001b[1;33m\u001b[0m\u001b[1;33m\u001b[0m\u001b[0m\n\u001b[1;32m---> 32\u001b[1;33m \u001b[0mmodel\u001b[0m\u001b[1;33m.\u001b[0m\u001b[0mfit\u001b[0m\u001b[1;33m(\u001b[0m\u001b[0mx_train\u001b[0m\u001b[1;33m,\u001b[0m \u001b[0my_train\u001b[0m\u001b[1;33m,\u001b[0m \u001b[0mepochs\u001b[0m\u001b[1;33m=\u001b[0m\u001b[1;36m10\u001b[0m\u001b[1;33m,\u001b[0m \u001b[0mbatch_size\u001b[0m\u001b[1;33m=\u001b[0m\u001b[1;36m32\u001b[0m\u001b[1;33m,\u001b[0m \u001b[0mvalidation_data\u001b[0m\u001b[1;33m=\u001b[0m\u001b[1;33m(\u001b[0m\u001b[0mx_test\u001b[0m\u001b[1;33m,\u001b[0m \u001b[0my_test\u001b[0m\u001b[1;33m)\u001b[0m\u001b[1;33m)\u001b[0m\u001b[1;33m\u001b[0m\u001b[1;33m\u001b[0m\u001b[0m\n\u001b[0m\u001b[0;32m     33\u001b[0m \u001b[1;33m\u001b[0m\u001b[0m\n\u001b[0;32m     34\u001b[0m \u001b[1;31m# Evaluate the model\u001b[0m\u001b[1;33m\u001b[0m\u001b[1;33m\u001b[0m\u001b[0m\n",
      "\u001b[1;32m~\\anaconda3\\lib\\site-packages\\keras\\src\\utils\\traceback_utils.py\u001b[0m in \u001b[0;36merror_handler\u001b[1;34m(*args, **kwargs)\u001b[0m\n",
      "\u001b[1;32m~\\anaconda3\\lib\\site-packages\\tensorflow\\python\\eager\\execute.py\u001b[0m in \u001b[0;36mquick_execute\u001b[1;34m(op_name, num_outputs, inputs, attrs, ctx, name)\u001b[0m\n\u001b[0;32m     51\u001b[0m   \u001b[1;32mtry\u001b[0m\u001b[1;33m:\u001b[0m\u001b[1;33m\u001b[0m\u001b[1;33m\u001b[0m\u001b[0m\n\u001b[0;32m     52\u001b[0m     \u001b[0mctx\u001b[0m\u001b[1;33m.\u001b[0m\u001b[0mensure_initialized\u001b[0m\u001b[1;33m(\u001b[0m\u001b[1;33m)\u001b[0m\u001b[1;33m\u001b[0m\u001b[1;33m\u001b[0m\u001b[0m\n\u001b[1;32m---> 53\u001b[1;33m     tensors = pywrap_tfe.TFE_Py_Execute(ctx._handle, device_name, op_name,\n\u001b[0m\u001b[0;32m     54\u001b[0m                                         inputs, attrs, num_outputs)\n\u001b[0;32m     55\u001b[0m   \u001b[1;32mexcept\u001b[0m \u001b[0mcore\u001b[0m\u001b[1;33m.\u001b[0m\u001b[0m_NotOkStatusException\u001b[0m \u001b[1;32mas\u001b[0m \u001b[0me\u001b[0m\u001b[1;33m:\u001b[0m\u001b[1;33m\u001b[0m\u001b[1;33m\u001b[0m\u001b[0m\n",
      "\u001b[1;31mUnimplementedError\u001b[0m: Graph execution error:\n\nDetected at node binary_crossentropy/Cast defined at (most recent call last):\n  File \"C:\\Users\\eddcr\\anaconda3\\lib\\runpy.py\", line 197, in _run_module_as_main\n\n  File \"C:\\Users\\eddcr\\anaconda3\\lib\\runpy.py\", line 87, in _run_code\n\n  File \"C:\\Users\\eddcr\\anaconda3\\lib\\site-packages\\ipykernel_launcher.py\", line 17, in <module>\n\n  File \"C:\\Users\\eddcr\\anaconda3\\lib\\site-packages\\traitlets\\config\\application.py\", line 846, in launch_instance\n\n  File \"C:\\Users\\eddcr\\anaconda3\\lib\\site-packages\\ipykernel\\kernelapp.py\", line 712, in start\n\n  File \"C:\\Users\\eddcr\\anaconda3\\lib\\site-packages\\tornado\\platform\\asyncio.py\", line 199, in start\n\n  File \"C:\\Users\\eddcr\\anaconda3\\lib\\asyncio\\base_events.py\", line 601, in run_forever\n\n  File \"C:\\Users\\eddcr\\anaconda3\\lib\\asyncio\\base_events.py\", line 1905, in _run_once\n\n  File \"C:\\Users\\eddcr\\anaconda3\\lib\\asyncio\\events.py\", line 80, in _run\n\n  File \"C:\\Users\\eddcr\\anaconda3\\lib\\site-packages\\ipykernel\\kernelbase.py\", line 510, in dispatch_queue\n\n  File \"C:\\Users\\eddcr\\anaconda3\\lib\\site-packages\\ipykernel\\kernelbase.py\", line 499, in process_one\n\n  File \"C:\\Users\\eddcr\\anaconda3\\lib\\site-packages\\ipykernel\\kernelbase.py\", line 406, in dispatch_shell\n\n  File \"C:\\Users\\eddcr\\anaconda3\\lib\\site-packages\\ipykernel\\kernelbase.py\", line 730, in execute_request\n\n  File \"C:\\Users\\eddcr\\anaconda3\\lib\\site-packages\\ipykernel\\ipkernel.py\", line 390, in do_execute\n\n  File \"C:\\Users\\eddcr\\anaconda3\\lib\\site-packages\\ipykernel\\zmqshell.py\", line 528, in run_cell\n\n  File \"C:\\Users\\eddcr\\anaconda3\\lib\\site-packages\\IPython\\core\\interactiveshell.py\", line 2914, in run_cell\n\n  File \"C:\\Users\\eddcr\\anaconda3\\lib\\site-packages\\IPython\\core\\interactiveshell.py\", line 2960, in _run_cell\n\n  File \"C:\\Users\\eddcr\\anaconda3\\lib\\site-packages\\IPython\\core\\async_helpers.py\", line 78, in _pseudo_sync_runner\n\n  File \"C:\\Users\\eddcr\\anaconda3\\lib\\site-packages\\IPython\\core\\interactiveshell.py\", line 3185, in run_cell_async\n\n  File \"C:\\Users\\eddcr\\anaconda3\\lib\\site-packages\\IPython\\core\\interactiveshell.py\", line 3377, in run_ast_nodes\n\n  File \"C:\\Users\\eddcr\\anaconda3\\lib\\site-packages\\IPython\\core\\interactiveshell.py\", line 3457, in run_code\n\n  File \"C:\\Users\\eddcr\\AppData\\Local\\Temp\\ipykernel_20144\\867447187.py\", line 32, in <module>\n\n  File \"C:\\Users\\eddcr\\anaconda3\\lib\\site-packages\\keras\\src\\utils\\traceback_utils.py\", line 65, in error_handler\n\n  File \"C:\\Users\\eddcr\\anaconda3\\lib\\site-packages\\keras\\src\\engine\\training.py\", line 1807, in fit\n\n  File \"C:\\Users\\eddcr\\anaconda3\\lib\\site-packages\\keras\\src\\engine\\training.py\", line 1401, in train_function\n\n  File \"C:\\Users\\eddcr\\anaconda3\\lib\\site-packages\\keras\\src\\engine\\training.py\", line 1384, in step_function\n\n  File \"C:\\Users\\eddcr\\anaconda3\\lib\\site-packages\\keras\\src\\engine\\training.py\", line 1373, in run_step\n\n  File \"C:\\Users\\eddcr\\anaconda3\\lib\\site-packages\\keras\\src\\engine\\training.py\", line 1151, in train_step\n\n  File \"C:\\Users\\eddcr\\anaconda3\\lib\\site-packages\\keras\\src\\engine\\training.py\", line 1209, in compute_loss\n\n  File \"C:\\Users\\eddcr\\anaconda3\\lib\\site-packages\\keras\\src\\engine\\compile_utils.py\", line 277, in __call__\n\n  File \"C:\\Users\\eddcr\\anaconda3\\lib\\site-packages\\keras\\src\\losses.py\", line 143, in __call__\n\n  File \"C:\\Users\\eddcr\\anaconda3\\lib\\site-packages\\keras\\src\\losses.py\", line 270, in call\n\n  File \"C:\\Users\\eddcr\\anaconda3\\lib\\site-packages\\keras\\src\\losses.py\", line 2521, in binary_crossentropy\n\nCast string to float is not supported\n\t [[{{node binary_crossentropy/Cast}}]] [Op:__inference_train_function_10902]"
     ]
    }
   ],
   "source": [
    "import pandas as pd\n",
    "from sklearn.model_selection import train_test_split\n",
    "from sklearn.preprocessing import StandardScaler\n",
    "from sklearn.pipeline import make_pipeline\n",
    "from sklearn.metrics import accuracy_score, precision_score, recall_score\n",
    "from tensorflow.keras.models import Sequential\n",
    "from tensorflow.keras.layers import Dense\n",
    "\n",
    "# Load data\n",
    "df = pd.read_csv('coords.csv')\n",
    "x = df.drop('class', axis=1)\n",
    "y = df['class']\n",
    "\n",
    "# Split data\n",
    "x_train, x_test, y_train, y_test = train_test_split(x, y, test_size=0.2, random_state=50)\n",
    "\n",
    "# Standardize data\n",
    "scaler = StandardScaler()\n",
    "x_train = scaler.fit_transform(x_train)\n",
    "x_test = scaler.transform(x_test)\n",
    "\n",
    "# Build neural network model\n",
    "model = Sequential([\n",
    "    Dense(64, activation='relu', input_shape=(x_train.shape[1],)),\n",
    "    Dense(1, activation='sigmoid')\n",
    "])\n",
    "\n",
    "# Compile the model\n",
    "model.compile(optimizer='adam', loss='binary_crossentropy', metrics=['accuracy'])\n",
    "\n",
    "# Train the model for 10 epochs\n",
    "model.fit(x_train, y_train, epochs=10, batch_size=32, validation_data=(x_test, y_test))\n",
    "\n",
    "# Evaluate the model\n",
    "yhat = (model.predict(x_test) > 0.5).astype(int)\n",
    "print(\"Neural Network Accuracy:\", accuracy_score(y_test, yhat))\n",
    "print(\"Neural Network Precision:\", precision_score(y_test, yhat, average=\"weighted\", pos_label=1))\n",
    "print(\"Neural Network Recall:\", recall_score(y_test, yhat, average=\"weighted\", pos_label=1))\n"
   ]
  },
  {
   "cell_type": "code",
   "execution_count": null,
   "id": "a5bf9075-ffc1-40d5-a6dc-13d9a99eb6b2",
   "metadata": {},
   "outputs": [],
   "source": []
  }
 ],
 "metadata": {
  "kernelspec": {
   "display_name": "Python 3 (ipykernel)",
   "language": "python",
   "name": "python3"
  },
  "language_info": {
   "codemirror_mode": {
    "name": "ipython",
    "version": 3
   },
   "file_extension": ".py",
   "mimetype": "text/x-python",
   "name": "python",
   "nbconvert_exporter": "python",
   "pygments_lexer": "ipython3",
   "version": "3.9.13"
  }
 },
 "nbformat": 4,
 "nbformat_minor": 5
}
